<!DOCTYPE html>
<html>
<head>
	<title>JS Promise</title>
</head>
<body>

<script type="text/javascript">

	// 0，基本的操作
	let myPromise = new Promise(function(resolve, reject) {
		console.log("doing something...");
		resolve("123");
	});

	myPromise.then(function(data) {
		console.log("data is :" + data);
	})


	// 1. Promise 新建后，传入的函数中的同步操作就会立即执行。
	// Resolve和Reject对应的callback会在当前event loop的所有同步操作执行完后再执行（即使promise里没有异步操作，resolve的执行还是会等到当前loop的同步操作结束后再执行）
	
	let myPromise2 = new Promise((resolve, reject) => {
		throw new Error("test error");
	});

	myPromise2.catch(err => {
		console.error(err);
	})

	console.log("outside promise 2");



	// 2. 注意，调用resolve或reject并不会终结Promise的参数函数的执行。
	let myPromise3 = new Promise((resolve, reject) => {
	  	resolve(1);
	  	console.log(2);
	}).then(r => {
	  	console.log(r);
	});


	// 3. resolve函数的参数除了正常的值以外，还可能是另一个Promise实例，此时另一个promise的状态会影响到外层promise的状态
	const myPromise4 = new Promise(function (resolve, reject) {
		setTimeout(() => reject(new Error('fail')), 100)
	})

	const myPromise5 = new Promise(function (resolve, reject) {
		setTimeout(() => resolve(myPromise4), 100)
	})

	myPromise5
	.then(result => console.log(result))
	.catch(error => console.error(error))
	// Error: fail


	// 4. 链式then (在一个promsie的then里return一个Promise对象)
	function doAsyncWithPromise(param) {
		return new Promise((resolve, reject) => {
			setTimeout(function(){
				console.log("doAsyncWithPromise: " + param);
				resolve();
			}, 100);
		});
	}

	doAsyncWithPromise(1)
		.then(() => {
			return doAsyncWithPromise(2);
		})
		.then(() => {
			return doAsyncWithPromise(3);
		});
	// 1, 2, 3


	// 5. Error处理，Promise 对象的错误具有“冒泡”性质，会一直向后传递，直到被捕获为止。也就是说，错误总是会被下一个catch语句捕获。
	// 一般来说，不要在then方法里面定义 Reject 状态的回调函数（即then的第二个参数），总是使用catch方法。
	const myPromise6 = new Promise((resolve, reject) => {
		setTimeout(function() {
			reject("Error: rejected");
		}, 100);
	});

	// 它们之中任何一个抛出的错误，都会被最后一个catch捕获
	myPromise6.then(() => {
		return doAsyncWithPromise(1);
	}).then(() => {
		let x = 1 + 1;
	}).catch((error) => {
		console.error(error);
	});

	// 跟传统的try/catch代码块不同的是，如果没有使用catch方法指定错误处理的回调函数，Promise 对象抛出的错误不会传递到外层代码，即不会有任何反应。

	// catch方法返回的还是一个 Promise 对象，因此后面还可以接着调用then方法。



	// 6. Promise.prototype.finally方法
	// finally方法用于指定不管 Promise 对象最后状态如何，都会执行的操作。该方法是 ES2018 引入标准的。
	const myPromise7 = new Promise((resolve, reject) => {
		setTimeout(() => {
			resolve(1);
		}, 100);
	});
	myPromise7.then(data => {
			console.log("myPromise7 data is: " + data);
		}).finally(() => {
			console.log("myPromise7 finally");
		});


	// 7. Promise.all()
	// 用于将多个 Promise 实例，包装成一个新的 Promise 实例
	// 只有都fulfilled才会fulfilled，只要一个rejected就会rejected
	// Promise.all方法接受一个数组作为参数，p1、p2、p3都是 Promise 实例，如果不是，就会先调用Promise.resolve方法，将参数转为 Promise 实例
	const myPromise8 = [1,2,3,4,5].map(function(param) {
		return doAsyncWithPromise(param);
	});

	// myPromise8 is an array of promises
	Promise.all(myPromise8).then(() => {
		console.log("All promises finished");
	});




	// 8. Promise.race()
	// Promise.race方法同样是将多个 Promise 实例, 只要多个promise之中有一个实例率先改变状态，包装后对象的状态就跟着改变
	const myPromise9 = [1,2,3].map(function(param) {
		return doAsyncWithPromise(param);
	})

	Promise.race(myPromise9).then(() => {
		console.log("One promise finished");
	});


</script>
</body>
</html>